Workbook

Sheet LEIA
A1: PT 520 – Procedimentos analíticos – ISA Energia Brasil 2025 (dados reais públicos; R$ mil)
A2: Cada análise indica o USO: Planejamento (NBC TA 315), Substantivo (NBC TA 520 it. 5) ou Revisão final (520 it. 6). Expectativa, precisão e limite definidos ANTES da comparação (colunas à esquerda).
A3: Explicações: "Documentada" = consta de documento público com página (RA não é auditado: indicado); "Hipótese" = não documentada.
A4: Células amarelas = dados transcritos (fonte e página na coluna própria) ou premissas; demais = fórmulas.
A5: Preparado por: matrícula 241003689 (execução assistida por IA) em 21/10/2026. Revisão humana: ____________ (em branco).

Sheet Parametros
A1: Parâmetro | B1: Valor | C1: Fonte / julgamento
A2: MG | B2: 139000 | C2: D-014
A3: ME | B3: 90000 | C3: D-014
A4: CT | B4: 7000 | C4: D-014
A5: Limite de investigação – substantivo (50% da ME) | B5: =B3*0.5 -> 45000 | C5: Julgamento: diferença aceitável sem exame adicional (520 it. 5(d), A16) – metade da ME por haver outras fontes de distorção na conta
A6: Limite – revisão final: |variação| ≥ ME e ≥ 10% | B6: =B3 -> 90000 | C6: Julgamento (520 it. 6)

Sheet RevisaoFinal_variacoes
A1: Cód. | B1: Linha (consolidado) | C1: 2025 | D1: 2024 | E1: Variação | F1: Var. % | G1: Sinalizada? | H1: Explicação | I1: Tipo | J1: Fonte
A2: A01 | B2: Caixa e equivalentes de caixa | C2: 1356062 | D2: 2914747 | E2: =C2-D2 -> -1558685 | F2: =IF(D2=0,"",E2/ABS(D2)) -> -0.53475825 | G2: =IF(AND(ABS(E2)>=Parametros!$B$6,OR(D2=0,ABS(N(F2))>=0.1)),"SIM","não") -> SIM | H2: Caixa reduzido; aplicações e investimentos em obras e dividendos pagos (DFC) | I2: Documentada | J2: F0003 p.27 (DFC)
A3: A02 | B3: Aplicações financeiras | C3: 808924 | D3: 485995 | E3: =C3-D3 -> 322929 | F3: =IF(D3=0,"",E3/ABS(D3)) -> 0.6644698 | G3: =IF(AND(ABS(E3)>=Parametros!$B$6,OR(D3=0,ABS(N(F3))>=0.1)),"SIM","não") -> SIM | H3: Aumento de aplicações financeiras (composição na nota 6.5; motivo: caixa de emissões de 2025 – RA) | I3: Documentada (RA) | J3: F0003 nota 6.5; p.13
A4: A03 | B4: Ativos da concessão (circulante) | C4: 4106084 | D4: 3604640 | E4: =C4-D4 -> 501444 | F4: =IF(D4=0,"",E4/ABS(D4)) -> 0.1391107 | G4: =IF(AND(ABS(E4)>=Parametros!$B$6,OR(D4=0,ABS(N(F4))>=0.1)),"SIM","não") -> SIM | H4: Circulante da concessão acompanha recebimentos dos 12 meses seguintes; aumento da RAP (REH 3.481) | I4: Hipótese parcial | J4: F0003 p.45, 101
A5: A04 | B5: Estoques (circulante) | C5: 72704 | D5: 94384 | E5: =C5-D5 -> -21680 | F5: =IF(D5=0,"",E5/ABS(D5)) -> -0.22969995 | G5: =IF(AND(ABS(E5)>=Parametros!$B$6,OR(D5=0,ABS(N(F5))>=0.1)),"SIM","não") -> não
A6: A05 | B6: Tributos e contribuições a compensar | C6: 229311 | D6: 453046 | E6: =C6-D6 -> -223735 | F6: =IF(D6=0,"",E6/ABS(D6)) -> -0.4938461 | G6: =IF(AND(ABS(E6)>=Parametros!$B$6,OR(D6=0,ABS(N(F6))>=0.1)),"SIM","não") -> SIM | H6: Compensação de tributos | I6: Hipótese | J6: —
A7: A06 | B7: Instrumentos financeiros derivativos (circulante) | C7: 37384 | D7: 41658 | E7: =C7-D7 -> -4274 | F7: =IF(D7=0,"",E7/ABS(D7)) -> -0.10259734 | G7: =IF(AND(ABS(E7)>=Parametros!$B$6,OR(D7=0,ABS(N(F7))>=0.1)),"SIM","não") -> não
A8: A07 | B8: Créditos com partes relacionadas | C8: 126579 | D8: 142546 | E8: =C8-D8 -> -15967 | F8: =IF(D8=0,"",E8/ABS(D8)) -> -0.11201296 | G8: =IF(AND(ABS(E8)>=Parametros!$B$6,OR(D8=0,ABS(N(F8))>=0.1)),"SIM","não") -> não
A9: A08 | B9: Outros (circulante) | C9: 350391 | D9: 202433 | E9: =C9-D9 -> 147958 | F9: =IF(D9=0,"",E9/ABS(D9)) -> 0.73089862 | G9: =IF(AND(ABS(E9)>=Parametros!$B$6,OR(D9=0,ABS(N(F9))>=0.1)),"SIM","não") -> SIM | H9: Outros ativos circulantes – composição não detalhada no BP | I9: Hipótese | J9: —
A10: A09 | B10: Total do ativo circulante | C10: 7087439 | D10: 7939449 | E10: =C10-D10 -> -852010 | F10: =IF(D10=0,"",E10/ABS(D10)) -> -0.10731349 | G10: =IF(AND(ABS(E10)>=Parametros!$B$6,OR(D10=0,ABS(N(F10))>=0.1)),"SIM","não") -> SIM | H10: Subtotal – variação explicada pelas linhas componentes | I10: Subtotal | J10: —
A11: A10 | B11: Ativos da concessão (realizável a LP) | C11: 32325214 | D11: 27442183 | E11: =C11-D11 -> 4883031 | F11: =IF(D11=0,"",E11/ABS(D11)) -> 0.17793887 | G11: =IF(AND(ABS(E11)>=Parametros!$B$6,OR(D11=0,ABS(N(F11))>=0.1)),"SIM","não") -> SIM | H11: Receita de infraestrutura 6.330.048 e remuneração (rollforward 5.5) | I11: Documentada | J11: F0003 p.47
A12: A11 | B12: Valores a receber - Secretaria da Fazenda | C12: 2760806 | D12: 2564527 | E12: =C12-D12 -> 196279 | F12: =IF(D12=0,"",E12/ABS(D12)) -> 0.076536141 | G12: =IF(AND(ABS(E12)>=Parametros!$B$6,OR(D12=0,ABS(N(F12))>=0.1)),"SIM","não") -> não | H12: Atualização do recebível SEFAZ (Lei 4.819/58) | I12: Documentada | J12: F0003 nota 9.2 (p.69–72)
A13: A12 | B13: Cauções e depósitos vinculados | C13: 46049 | D13: 43650 | E13: =C13-D13 -> 2399 | F13: =IF(D13=0,"",E13/ABS(D13)) -> 0.054959908 | G13: =IF(AND(ABS(E13)>=Parametros!$B$6,OR(D13=0,ABS(N(F13))>=0.1)),"SIM","não") -> não
A14: A13 | B14: Estoques (realizável a LP) | C14: 94871 | D14: 140344 | E14: =C14-D14 -> -45473 | F14: =IF(D14=0,"",E14/ABS(D14)) -> -0.324011 | G14: =IF(AND(ABS(E14)>=Parametros!$B$6,OR(D14=0,ABS(N(F14))>=0.1)),"SIM","não") -> não
A15: A14 | B15: Instrumentos financeiros derivativos (LP) | C15: 20406 | D15: 84715 | E15: =C15-D15 -> -64309 | F15: =IF(D15=0,"",E15/ABS(D15)) -> -0.75912176 | G15: =IF(AND(ABS(E15)>=Parametros!$B$6,OR(D15=0,ABS(N(F15))>=0.1)),"SIM","não") -> não
A16: A15 | B16: Outros (realizável a LP) | C16: 95413 | D16: 142798 | E16: =C16-D16 -> -47385 | F16: =IF(D16=0,"",E16/ABS(D16)) -> -0.33183238 | G16: =IF(AND(ABS(E16)>=Parametros!$B$6,OR(D16=0,ABS(N(F16))>=0.1)),"SIM","não") -> não
A17: A16 | B17: Total do realizável a longo prazo | C17: 35342759 | D17: 30418217 | E17: =C17-D17 -> 4924542 | F17: =IF(D17=0,"",E17/ABS(D17)) -> 0.1618945 | G17: =IF(AND(ABS(E17)>=Parametros!$B$6,OR(D17=0,ABS(N(F17))>=0.1)),"SIM","não") -> SIM | H17: Subtotal – variação explicada pelas linhas componentes | I17: Subtotal | J17: —
A18: A17 | B18: Investimentos | C18: 4154815 | D18: 4354888 | E18: =C18-D18 -> -200073 | F18: =IF(D18=0,"",E18/ABS(D18)) -> -0.045942169 | G18: =IF(AND(ABS(E18)>=Parametros!$B$6,OR(D18=0,ABS(N(F18))>=0.1)),"SIM","não") -> não | H18: Equivalência 511.049 menos dividendos/JCP de JVs | I18: Hipótese parcial | J18: F0003 p.23, 25, nota 7
A19: A18 | B19: Imobilizado | C19: 180126 | D19: 153613 | E19: =C19-D19 -> 26513 | F19: =IF(D19=0,"",E19/ABS(D19)) -> 0.17259607 | G19: =IF(AND(ABS(E19)>=Parametros!$B$6,OR(D19=0,ABS(N(F19))>=0.1)),"SIM","não") -> não
A20: A19 | B20: Intangível | C20: 436233 | D20: 438465 | E20: =C20-D20 -> -2232 | F20: =IF(D20=0,"",E20/ABS(D20)) -> -0.0050904861 | G20: =IF(AND(ABS(E20)>=Parametros!$B$6,OR(D20=0,ABS(N(F20))>=0.1)),"SIM","não") -> não
A21: A20 | B21: Subtotal investimentos, imobilizado e intangível | C21: 4771174 | D21: 4946966 | E21: =C21-D21 -> -175792 | F21: =IF(D21=0,"",E21/ABS(D21)) -> -0.035535316 | G21: =IF(AND(ABS(E21)>=Parametros!$B$6,OR(D21=0,ABS(N(F21))>=0.1)),"SIM","não") -> não
A22: A21 | B22: Total do ativo não circulante | C22: 40113933 | D22: 35365183 | E22: =C22-D22 -> 4748750 | F22: =IF(D22=0,"",E22/ABS(D22)) -> 0.13427755 | G22: =IF(AND(ABS(E22)>=Parametros!$B$6,OR(D22=0,ABS(N(F22))>=0.1)),"SIM","não") -> SIM | H22: Subtotal – variação explicada pelas linhas componentes | I22: Subtotal | J22: —
A23: A22 | B23: Total do ativo | C23: 47201372 | D23: 43304632 | E23: =C23-D23 -> 3896740 | F23: =IF(D23=0,"",E23/ABS(D23)) -> 0.089984369 | G23: =IF(AND(ABS(E23)>=Parametros!$B$6,OR(D23=0,ABS(N(F23))>=0.1)),"SIM","não") -> não
A24: P01 | B24: Empréstimos e financiamentos (circulante) | C24: 90082 | D24: 82056 | E24: =C24-D24 -> 8026 | F24: =IF(D24=0,"",E24/ABS(D24)) -> 0.097811251 | G24: =IF(AND(ABS(E24)>=Parametros!$B$6,OR(D24=0,ABS(N(F24))>=0.1)),"SIM","não") -> não
A25: P02 | B25: Debêntures (circulante) | C25: 496001 | D25: 1109914 | E25: =C25-D25 -> -613913 | F25: =IF(D25=0,"",E25/ABS(D25)) -> -0.55311763 | G25: =IF(AND(ABS(E25)>=Parametros!$B$6,OR(D25=0,ABS(N(F25))>=0.1)),"SIM","não") -> SIM | H25: Amortização de debêntures no circulante | I25: Documentada | J25: F0003 nota 6.1
A26: P03 | B26: Arrendamento (circulante) | C26: 18677 | D26: 12020 | E26: =C26-D26 -> 6657 | F26: =IF(D26=0,"",E26/ABS(D26)) -> 0.55382696 | G26: =IF(AND(ABS(E26)>=Parametros!$B$6,OR(D26=0,ABS(N(F26))>=0.1)),"SIM","não") -> não
A27: P04 | B27: Fornecedores | C27: 254445 | D27: 182169 | E27: =C27-D27 -> 72276 | F27: =IF(D27=0,"",E27/ABS(D27)) -> 0.39675247 | G27: =IF(AND(ABS(E27)>=Parametros!$B$6,OR(D27=0,ABS(N(F27))>=0.1)),"SIM","não") -> não
A28: P05 | B28: Tributos e encargos sociais a recolher | C28: 213325 | D28: 139146 | E28: =C28-D28 -> 74179 | F28: =IF(D28=0,"",E28/ABS(D28)) -> 0.53310192 | G28: =IF(AND(ABS(E28)>=Parametros!$B$6,OR(D28=0,ABS(N(F28))>=0.1)),"SIM","não") -> não
A29: P06 | B29: Encargos regulatórios a recolher (circulante) | C29: 69203 | D29: 66750 | E29: =C29-D29 -> 2453 | F29: =IF(D29=0,"",E29/ABS(D29)) -> 0.036749064 | G29: =IF(AND(ABS(E29)>=Parametros!$B$6,OR(D29=0,ABS(N(F29))>=0.1)),"SIM","não") -> não
A30: P07 | B30: Juros sobre capital próprio e dividendos a pagar | C30: 422540 | D30: 1329622 | E30: =C30-D30 -> -907082 | F30: =IF(D30=0,"",E30/ABS(D30)) -> -0.68221043 | G30: =IF(AND(ABS(E30)>=Parametros!$B$6,OR(D30=0,ABS(N(F30))>=0.1)),"SIM","não") -> SIM | H30: Pagamento de JCP/dividendos de 2024 (1.329.622) | I30: Documentada | J30: F0003 nota 15.2.2
A31: P08 | B31: Obrigações trabalhistas | C31: 79962 | D31: 71658 | E31: =C31-D31 -> 8304 | F31: =IF(D31=0,"",E31/ABS(D31)) -> 0.11588378 | G31: =IF(AND(ABS(E31)>=Parametros!$B$6,OR(D31=0,ABS(N(F31))>=0.1)),"SIM","não") -> não
A32: P09 | B32: Instrumentos financeiros derivativos (circulante) | C32: 2916 | D32: 0 | E32: =C32-D32 -> 2916 | F32: =IF(D32=0,"",E32/ABS(D32)) | G32: =IF(AND(ABS(E32)>=Parametros!$B$6,OR(D32=0,ABS(N(F32))>=0.1)),"SIM","não") -> não
A33: P10 | B33: Provisões - Capex | C33: 210460 | D33: 244333 | E33: =C33-D33 -> -33873 | F33: =IF(D33=0,"",E33/ABS(D33)) -> -0.13863457 | G33: =IF(AND(ABS(E33)>=Parametros!$B$6,OR(D33=0,ABS(N(F33))>=0.1)),"SIM","não") -> não
A34: P11 | B34: Outros (circulante) | C34: 29160 | D34: 27150 | E34: =C34-D34 -> 2010 | F34: =IF(D34=0,"",E34/ABS(D34)) -> 0.074033149 | G34: =IF(AND(ABS(E34)>=Parametros!$B$6,OR(D34=0,ABS(N(F34))>=0.1)),"SIM","não") -> não
A35: P12 | B35: Total do passivo circulante | C35: 1886771 | D35: 3264818 | E35: =C35-D35 -> -1378047 | F35: =IF(D35=0,"",E35/ABS(D35)) -> -0.42208999 | G35: =IF(AND(ABS(E35)>=Parametros!$B$6,OR(D35=0,ABS(N(F35))>=0.1)),"SIM","não") -> SIM | H35: Subtotal – variação explicada pelas linhas componentes | I35: Subtotal | J35: —
A36: P13 | B36: Empréstimos e financiamentos (não circulante) | C36: 669117 | D36: 651766 | E36: =C36-D36 -> 17351 | F36: =IF(D36=0,"",E36/ABS(D36)) -> 0.026621518 | G36: =IF(AND(ABS(E36)>=Parametros!$B$6,OR(D36=0,ABS(N(F36))>=0.1)),"SIM","não") -> não
A37: P14 | B37: Debêntures (não circulante) | C37: 14696513 | D37: 11392559 | E37: =C37-D37 -> 3303954 | F37: =IF(D37=0,"",E37/ABS(D37)) -> 0.29000982 | G37: =IF(AND(ABS(E37)>=Parametros!$B$6,OR(D37=0,ABS(N(F37))>=0.1)),"SIM","não") -> SIM | H37: Emissões das 18ª, 19ª e 20ª debêntures em 2025 | I37: Documentada (RA) | J37: F0003 p.13
A38: P15 | B38: Arrendamento (não circulante) | C38: 36959 | D38: 25489 | E38: =C38-D38 -> 11470 | F38: =IF(D38=0,"",E38/ABS(D38)) -> 0.44999804 | G38: =IF(AND(ABS(E38)>=Parametros!$B$6,OR(D38=0,ABS(N(F38))>=0.1)),"SIM","não") -> não
A39: P16 | B39: PIS e COFINS diferidos | C39: 2966130 | D39: 2493513 | E39: =C39-D39 -> 472617 | F39: =IF(D39=0,"",E39/ABS(D39)) -> 0.18953861 | G39: =IF(AND(ABS(E39)>=Parametros!$B$6,OR(D39=0,ABS(N(F39))>=0.1)),"SIM","não") -> SIM | H39: PIS/COFINS diferidos acompanham receita de infraestrutura e remuneração | I39: Documentada | J39: F0003 p.44
A40: P17 | B40: Imposto de renda e contribuição social diferidos | C40: 5287595 | D40: 5175168 | E40: =C40-D40 -> 112427 | F40: =IF(D40=0,"",E40/ABS(D40)) -> 0.021724319 | G40: =IF(AND(ABS(E40)>=Parametros!$B$6,OR(D40=0,ABS(N(F40))>=0.1)),"SIM","não") -> não
...

Sheet S1_Infra_margem
A1: Elemento | B1: Valor | C1: Fonte / fórmula
A2: USO: procedimento analítico SUBSTANTIVO (R02 exatidão/ocorrência) – complementa testes de detalhe (PT 530 [SD]); dados auditados pelo antecessor/DF publicada | C2: 520 it. 5(a)
A3: Custo de implementação 2025 | B3: 5092819 | C3: F0003 p.100 (16.4)
A4: Receita de infraestrutura 2024 | B4: 4461867 | C4: F0003 p.100
A5: Custo de implementação 2024 | B5: 3634525 | C5: F0003 p.100
A6: Margem 2024 sobre custo = B4/B5 − 1 | B6: =B4/B5-1 -> 0.22763415 | C6: Expectativa: margem estável sobre custo
A7: EXPECTATIVA receita 2025 = custo 2025 × (1 + margem 2024) | B7: =B3*(1+B6) -> 6252118.5 | C7: 520 it. 5(c)
A8: Receita de infraestrutura 2025 registrada | B8: 6330048 | C8: F0003 p.47, 100
A9: Diferença = registrado − esperado | B9: =B8-B7 -> 77929.488
A10: Limite de investigação | B10: =Parametros!B5 -> 45000 | C10: 520 it. 5(d)
A11: Investigar? | B11: =IF(ABS(B9)>B10,"SIM","não") -> SIM | C11: 520 it. 7
A12: Precisão: margem por projeto varia (F0003 p.100: "margem estimada para cada projeto"); mix de projetos novos muda a média | C12: Avaliação it. 5(c): precisão MODERADA
A13: Explicação documentada | B13: Margem percebida 19,55% (2025) × 18,54% (2024) sobre receita; mix com Piraquê, Serra Dourada, Itatiaia | C13: F0003 p.9, 100 – documentada (nota 16.4 auditada)
A14: Margem 2025 sobre custo | B14: =B8/B3-1 -> 0.24293598
A15: Diferença explicada pela mudança de margem = custo × (margem25 − margem24) | B15: =B3*(B14-B6) -> 77929.488 | C15: Deve igualar B9
A16: Resíduo (zero por identidade algébrica: a ponte só reexpressa a diferença como mudança de margem; NÃO é evidência independente da margem) | B16: =B9-B15 -> 4.6566129e-10 | C16: Margens por projeto exigem evidência de projeto [PA]; ver PT 530 TD-01 R2 [SD]

Sheet S2_OEM
A1: Elemento | B1: Valor | C1: Fonte / fórmula
A2: USO: SUBSTANTIVO (R03/O&M exatidão) – expectativa a partir da RAP
A3: Receita de O&M 2024 | B3: 1363819 | C3: F0003 p.100
A4: RAP total ciclo 2024/25 (Total 2024 da tabela) | B4: 4308721 | C4: F0003 p.101
A5: RAP total ciclo 2025/26 | B5: 4694108 | C5: F0003 p.101
A6: Fator RAP médio do ano civil 2025 = (½ ciclo 24/25 + ½ ciclo 25/26) / RAP 24/25 médio do ano civil 2024 (aprox.) | B6: =(0.5*B4+0.5*B5)/B4 -> 1.0447217 | C6: Julgamento: RAP de jul–jun; 2024 tratado como ciclo 24/25 (simplificação)
A7: EXPECTATIVA O&M 2025 = O&M 2024 × fator | B7: =B3*B6 -> 1424811.4
A8: Registrado 2025 | B8: 1264867 | C8: F0003 p.100
A9: Diferença | B9: =B8-B7 -> -159944.36
A10: Limite | B10: =Parametros!B5 -> 45000
A11: Investigar? | B11: =IF(ABS(B9)>B10,"SIM","não") -> SIM
A12: Explicação documentada (RA, não auditado): (i) redução de parcela de ajuste e antecipações −129.508; (ii) RTP 2024 – repasse de eficiência + IPCA −288; (iii) encargos e PV +30.844 | B12: =-129508-288+30844 -> -98952 | C12: F0003 p.10
A13: Variação real 2025 − 2024 | B13: =B8-B3 -> -98952 | C13: Deve igualar B12
A14: Ponte da administração fecha? | B14: =IF(B12=B13,"SIM","NÃO") -> SIM
A15: Conclusão: expectativa por RAP NÃO é precisa (parcela de ajuste é volátil e a RAP inclui remuneração de ativos); serve para PLANEJAMENTO, não como substantivo | C15: 520 it. 5(c) e A15

Sheet S3_Remuneracao
A1: Elemento | B1: Valor | C1: Fonte / fórmula
A2: USO: SUBSTANTIVO pretendido (R01) – avaliar se a expectativa é precisa
A3: Ativo contratual 31/12/2023 | B3: 25826247 | C3: F0011 p.44
A4: Ativo contratual 31/12/2024 | B4: 30853759 | C4: F0003 p.45
A5: Ativo contratual 31/12/2025 | B5: 36273035 | C5: F0003 p.45
A6: Remuneração 2024 | B6: 3028571 | C6: F0003 p.47
A7: Remuneração 2025 publicada | B7: 2949237 | C7: F0003 p.47
A8: Efeito REH 3.466/2025 (item não recorrente) | B8: -898790 | C8: F0003 p.9, 46
A9: Remuneração 2025 sem REH | B9: =B7-B8 -> 3848027
A10: Rendimento efetivo 2024 = rem / saldo médio | B10: =B6/AVERAGE(B3,B4) -> 0.10686559
A11: EXPECTATIVA 2025 = rendimento 2024 × saldo médio 2025 | B11: =B10*AVERAGE(B4,B5) -> 3586772.1 | C11: 520 it. 5(c)
A12: Diferença (sem REH) = B9 − B11 | B12: =B9-B11 -> 261254.94
A13: Limite | B13: =Parametros!B5 -> 45000
A14: Investigar? | B14: =IF(ABS(B12)>B13,"SIM","não") -> SIM
A15: Ponte da administração (RA): taxa implícita +241.090; WACC (Despacho 882/2025) +229.917; VNR +167.705; reajuste 25/26 +160.812; IPCA +19.932; REH −898.790 | B15: =241090+229917+167705+160812+19932-898790 -> -79334 | C15: F0003 p.9 (RA)
A16: Variação real 2025 − 2024 | B16: =B7-B6 -> -79334
A17: Ponte fecha? | B17: =IF(B15=B16,"SIM","NÃO") -> SIM
A18: Sensibilidade da expectativa: ±0,5 p.p. no rendimento × saldo médio | B18: =0.005*AVERAGE(B4,B5) -> 167816.98 | C18: Precisão: 0,5 p.p. ≈ 168 mil > limite → expectativa NÃO suficientemente precisa (520 it. 5(c))
A19: Conclusão: uso como análise de PLANEJAMENTO/indicador; evidência substantiva vem do recálculo por contrato (PT 530 TD-05 [SD]; real [PA]) e do PT 540

Sheet Indicadores
A1: Indicador | B1: 2025 | C1: 2024 | D1: Fórmula | E1: Uso | F1: Leitura
A2: Margem de implementação (F0003 16.4) | B2: =1-5092819/6330048 -> 0.19545334 | C2: =1-3634525/4461867 -> 0.18542507 | D2: 1 − custo/receita | E2: Planejamento | F2: Estável (19,6% × 18,5%)
A3: Margem de O&M | B3: =1-615219/1264867 -> 0.51360973 | C3: =1-594595/1363819 -> 0.56402206 | D3: 1 − custo/receita O&M | E3: Planejamento | F3: Queda de ~5 p.p. – receita caiu, custo subiu
A4: PIS+COFINS / receita bruta | B4: =(751760+162977)/10574132 -> 0.086507053 | C4: =(661538+143603)/8994821 -> 0.08951162 | D4: F0003 p.99 | E4: Revisão final | F4: Coerente com regime misto
A5: Encargos regulatórios / receita bruta | B5: =243923/10574132 -> 0.023067898 | C5: =219285/8994821 -> 0.024379029 | D5: F0003 p.99 | E5: Revisão final | F5: Estável
A6: Dívida bruta (P01+P02+P13+P14) | B6: =90082+496001+669117+14696513 -> 15951713 | C6: =82056+1109914+651766+11392559 -> 13236295 | D6: BP p.24 | E6: Planejamento
A7: Custo aparente da dívida = desp. financeiras / dívida média | B7: =1797455/AVERAGE(B6,C6) -> 0.12316394 | D7: Inclui encargos e variação monetária | E7: Revisão final | F7: CDI 14,26% e IPCA 4,46% (F0003 p.13) – coerente com dívida indexada a CDI e IPCA
A8: Lucro líquido / receita líquida | B8: =2511015/9411153 -> 0.26681268 | C8: =3552731/7966581 -> 0.44595429 | D8: DRE p.25 | E8: Revisão final | F8: Queda explicada por RTP 2024 e REH 3.466
A9: Equivalência / investimentos médios | B9: =511049/AVERAGE(4154815,4354888) -> 0.12010971 | D9: p.23, 25 | E9: Planejamento | F9: Retorno das JVs ~12%
